ERROR Internal Server Error: /api/graphql/
Traceback (most recent call last):
  File "c:\a\envs\django\lib\site-packages\graphene_django\settings.py", line 68, in import_from_string
    module = importlib.import_module(module_path)
  File "c:\a\envs\django\lib\importlib\__init__.py", line 109, in import_module
    return _bootstrap._gcd_import(name[level:], package, level)
  File "<frozen importlib._bootstrap>", line 2254, in _gcd_import
  File "<frozen importlib._bootstrap>", line 2237, in _find_and_load
  File "<frozen importlib._bootstrap>", line 2212, in _find_and_load_unlocked
  File "<frozen importlib._bootstrap>", line 321, in _call_with_frames_removed
  File "<frozen importlib._bootstrap>", line 2254, in _gcd_import
  File "<frozen importlib._bootstrap>", line 2237, in _find_and_load
  File "<frozen importlib._bootstrap>", line 2224, in _find_and_load_unlocked
ImportError: No module named 'app'

During handling of the above exception, another exception occurred:

Traceback (most recent call last):
  File "c:\a\envs\django\lib\site-packages\django\core\handlers\exception.py", line 39, in inner
    response = get_response(request)
  File "c:\a\envs\django\lib\site-packages\django\core\handlers\base.py", line 249, in _legacy_get_response
    response = self._get_response(request)
  File "c:\a\envs\django\lib\site-packages\django\core\handlers\base.py", line 187, in _get_response
    response = self.process_exception_by_middleware(e, request)
  File "c:\a\envs\django\lib\site-packages\django\core\handlers\base.py", line 185, in _get_response
    response = wrapped_callback(request, *callback_args, **callback_kwargs)
  File "c:\a\envs\django\lib\site-packages\django\views\generic\base.py", line 62, in view
    self = cls(**initkwargs)
  File "c:\a\envs\django\lib\site-packages\graphene_django\views.py", line 68, in __init__
    schema = graphene_settings.SCHEMA
  File "c:\a\envs\django\lib\site-packages\graphene_django\settings.py", line 110, in __getattr__
    val = perform_import(val, attr)
  File "c:\a\envs\django\lib\site-packages\graphene_django\settings.py", line 54, in perform_import
    return import_from_string(val, setting_name)
  File "c:\a\envs\django\lib\site-packages\graphene_django\settings.py", line 72, in import_from_string
    raise ImportError(msg)
ImportError: Could not import 'app.schema.schema' for Graphene setting 'SCHEMA'. ImportError: No module named 'app'.
ERROR "GET /api/graphql/ HTTP/1.1" 500 96069
ERROR Internal Server Error: /api/graphql/
Traceback (most recent call last):
  File "c:\a\envs\django\lib\site-packages\graphene_django\settings.py", line 68, in import_from_string
    module = importlib.import_module(module_path)
  File "c:\a\envs\django\lib\importlib\__init__.py", line 109, in import_module
    return _bootstrap._gcd_import(name[level:], package, level)
  File "<frozen importlib._bootstrap>", line 2254, in _gcd_import
  File "<frozen importlib._bootstrap>", line 2237, in _find_and_load
  File "<frozen importlib._bootstrap>", line 2224, in _find_and_load_unlocked
ImportError: No module named 'gqltest.api'

During handling of the above exception, another exception occurred:

Traceback (most recent call last):
  File "c:\a\envs\django\lib\site-packages\django\core\handlers\exception.py", line 39, in inner
    response = get_response(request)
  File "c:\a\envs\django\lib\site-packages\django\core\handlers\base.py", line 249, in _legacy_get_response
    response = self._get_response(request)
  File "c:\a\envs\django\lib\site-packages\django\core\handlers\base.py", line 187, in _get_response
    response = self.process_exception_by_middleware(e, request)
  File "c:\a\envs\django\lib\site-packages\django\core\handlers\base.py", line 185, in _get_response
    response = wrapped_callback(request, *callback_args, **callback_kwargs)
  File "c:\a\envs\django\lib\site-packages\django\views\generic\base.py", line 62, in view
    self = cls(**initkwargs)
  File "c:\a\envs\django\lib\site-packages\graphene_django\views.py", line 68, in __init__
    schema = graphene_settings.SCHEMA
  File "c:\a\envs\django\lib\site-packages\graphene_django\settings.py", line 110, in __getattr__
    val = perform_import(val, attr)
  File "c:\a\envs\django\lib\site-packages\graphene_django\settings.py", line 54, in perform_import
    return import_from_string(val, setting_name)
  File "c:\a\envs\django\lib\site-packages\graphene_django\settings.py", line 72, in import_from_string
    raise ImportError(msg)
ImportError: Could not import 'gqltest.api.schema' for Graphene setting 'SCHEMA'. ImportError: No module named 'gqltest.api'.
ERROR "GET /api/graphql/ HTTP/1.1" 500 96285
ERROR Internal Server Error: /api/graphql/
Traceback (most recent call last):
  File "c:\a\envs\django\lib\site-packages\graphene_django\settings.py", line 69, in import_from_string
    return getattr(module, class_name)
AttributeError: 'module' object has no attribute 'schema'

During handling of the above exception, another exception occurred:

Traceback (most recent call last):
  File "c:\a\envs\django\lib\site-packages\django\core\handlers\exception.py", line 39, in inner
    response = get_response(request)
  File "c:\a\envs\django\lib\site-packages\django\core\handlers\base.py", line 249, in _legacy_get_response
    response = self._get_response(request)
  File "c:\a\envs\django\lib\site-packages\django\core\handlers\base.py", line 187, in _get_response
    response = self.process_exception_by_middleware(e, request)
  File "c:\a\envs\django\lib\site-packages\django\core\handlers\base.py", line 185, in _get_response
    response = wrapped_callback(request, *callback_args, **callback_kwargs)
  File "c:\a\envs\django\lib\site-packages\django\views\generic\base.py", line 62, in view
    self = cls(**initkwargs)
  File "c:\a\envs\django\lib\site-packages\graphene_django\views.py", line 68, in __init__
    schema = graphene_settings.SCHEMA
  File "c:\a\envs\django\lib\site-packages\graphene_django\settings.py", line 110, in __getattr__
    val = perform_import(val, attr)
  File "c:\a\envs\django\lib\site-packages\graphene_django\settings.py", line 54, in perform_import
    return import_from_string(val, setting_name)
  File "c:\a\envs\django\lib\site-packages\graphene_django\settings.py", line 72, in import_from_string
    raise ImportError(msg)
ImportError: Could not import 'api.schema' for Graphene setting 'SCHEMA'. AttributeError: 'module' object has no attribute 'schema'.
ERROR "GET /api/graphql/ HTTP/1.1" 500 93234
ERROR Internal Server Error: /api/graphql/
Traceback (most recent call last):
  File "c:\a\envs\django\lib\site-packages\django\core\handlers\exception.py", line 39, in inner
    response = get_response(request)
  File "c:\a\envs\django\lib\site-packages\django\core\handlers\base.py", line 249, in _legacy_get_response
    response = self._get_response(request)
  File "c:\a\envs\django\lib\site-packages\django\core\handlers\base.py", line 187, in _get_response
    response = self.process_exception_by_middleware(e, request)
  File "c:\a\envs\django\lib\site-packages\django\core\handlers\base.py", line 185, in _get_response
    response = wrapped_callback(request, *callback_args, **callback_kwargs)
  File "c:\a\envs\django\lib\site-packages\django\views\generic\base.py", line 62, in view
    self = cls(**initkwargs)
  File "c:\a\envs\django\lib\site-packages\graphene_django\views.py", line 68, in __init__
    schema = graphene_settings.SCHEMA
  File "c:\a\envs\django\lib\site-packages\graphene_django\settings.py", line 110, in __getattr__
    val = perform_import(val, attr)
  File "c:\a\envs\django\lib\site-packages\graphene_django\settings.py", line 54, in perform_import
    return import_from_string(val, setting_name)
  File "c:\a\envs\django\lib\site-packages\graphene_django\settings.py", line 68, in import_from_string
    module = importlib.import_module(module_path)
  File "c:\a\envs\django\lib\importlib\__init__.py", line 109, in import_module
    return _bootstrap._gcd_import(name[level:], package, level)
  File "<frozen importlib._bootstrap>", line 2249, in _gcd_import
  File "<frozen importlib._bootstrap>", line 2201, in _sanity_check
ValueError: Empty module name
ERROR "GET /api/graphql/ HTTP/1.1" 500 90481
ERROR Internal Server Error: /api/graphql/
Traceback (most recent call last):
  File "c:\a\envs\django\lib\site-packages\graphene_django\settings.py", line 68, in import_from_string
    module = importlib.import_module(module_path)
  File "c:\a\envs\django\lib\importlib\__init__.py", line 109, in import_module
    return _bootstrap._gcd_import(name[level:], package, level)
  File "<frozen importlib._bootstrap>", line 2254, in _gcd_import
  File "<frozen importlib._bootstrap>", line 2237, in _find_and_load
  File "<frozen importlib._bootstrap>", line 2224, in _find_and_load_unlocked
ImportError: No module named 'gqltest.api'

During handling of the above exception, another exception occurred:

Traceback (most recent call last):
  File "c:\a\envs\django\lib\site-packages\django\core\handlers\exception.py", line 39, in inner
    response = get_response(request)
  File "c:\a\envs\django\lib\site-packages\django\core\handlers\base.py", line 249, in _legacy_get_response
    response = self._get_response(request)
  File "c:\a\envs\django\lib\site-packages\django\core\handlers\base.py", line 187, in _get_response
    response = self.process_exception_by_middleware(e, request)
  File "c:\a\envs\django\lib\site-packages\django\core\handlers\base.py", line 185, in _get_response
    response = wrapped_callback(request, *callback_args, **callback_kwargs)
  File "c:\a\envs\django\lib\site-packages\django\views\generic\base.py", line 62, in view
    self = cls(**initkwargs)
  File "c:\a\envs\django\lib\site-packages\graphene_django\views.py", line 68, in __init__
    schema = graphene_settings.SCHEMA
  File "c:\a\envs\django\lib\site-packages\graphene_django\settings.py", line 110, in __getattr__
    val = perform_import(val, attr)
  File "c:\a\envs\django\lib\site-packages\graphene_django\settings.py", line 54, in perform_import
    return import_from_string(val, setting_name)
  File "c:\a\envs\django\lib\site-packages\graphene_django\settings.py", line 72, in import_from_string
    raise ImportError(msg)
ImportError: Could not import 'gqltest.api.schema' for Graphene setting 'SCHEMA'. ImportError: No module named 'gqltest.api'.
ERROR "GET /api/graphql/ HTTP/1.1" 500 96285
ERROR Internal Server Error: /api/graphql/
Traceback (most recent call last):
  File "c:\a\envs\django\lib\site-packages\django\core\handlers\exception.py", line 39, in inner
    response = get_response(request)
  File "c:\a\envs\django\lib\site-packages\django\core\handlers\base.py", line 249, in _legacy_get_response
    response = self._get_response(request)
  File "c:\a\envs\django\lib\site-packages\django\core\handlers\base.py", line 187, in _get_response
    response = self.process_exception_by_middleware(e, request)
  File "c:\a\envs\django\lib\site-packages\django\core\handlers\base.py", line 185, in _get_response
    response = wrapped_callback(request, *callback_args, **callback_kwargs)
  File "c:\a\envs\django\lib\site-packages\django\views\generic\base.py", line 62, in view
    self = cls(**initkwargs)
  File "c:\a\envs\django\lib\site-packages\graphene_django\views.py", line 68, in __init__
    schema = graphene_settings.SCHEMA
  File "c:\a\envs\django\lib\site-packages\graphene_django\settings.py", line 110, in __getattr__
    val = perform_import(val, attr)
  File "c:\a\envs\django\lib\site-packages\graphene_django\settings.py", line 54, in perform_import
    return import_from_string(val, setting_name)
  File "c:\a\envs\django\lib\site-packages\graphene_django\settings.py", line 68, in import_from_string
    module = importlib.import_module(module_path)
  File "c:\a\envs\django\lib\importlib\__init__.py", line 109, in import_module
    return _bootstrap._gcd_import(name[level:], package, level)
  File "<frozen importlib._bootstrap>", line 2254, in _gcd_import
  File "<frozen importlib._bootstrap>", line 2237, in _find_and_load
  File "<frozen importlib._bootstrap>", line 2226, in _find_and_load_unlocked
  File "<frozen importlib._bootstrap>", line 1200, in _load_unlocked
  File "<frozen importlib._bootstrap>", line 1129, in _exec
  File "<frozen importlib._bootstrap>", line 1471, in exec_module
  File "<frozen importlib._bootstrap>", line 321, in _call_with_frames_removed
  File "c:\a\programming\django\graphql\src\api\schema.py", line 3, in <module>
    class User(DjangoObjectType):
  File "c:\a\programming\django\graphql\src\api\schema.py", line 4, in User
    class Meta:
  File "c:\a\programming\django\graphql\src\api\schema.py", line 5, in Meta
    model = UserModel
NameError: name 'UserModel' is not defined
ERROR "GET /api/graphql/ HTTP/1.1" 500 106658
ERROR Internal Server Error: /api/graphql/
Traceback (most recent call last):
  File "c:\a\envs\django\lib\site-packages\django\core\handlers\exception.py", line 39, in inner
    response = get_response(request)
  File "c:\a\envs\django\lib\site-packages\django\core\handlers\base.py", line 249, in _legacy_get_response
    response = self._get_response(request)
  File "c:\a\envs\django\lib\site-packages\django\core\handlers\base.py", line 187, in _get_response
    response = self.process_exception_by_middleware(e, request)
  File "c:\a\envs\django\lib\site-packages\django\core\handlers\base.py", line 185, in _get_response
    response = wrapped_callback(request, *callback_args, **callback_kwargs)
  File "c:\a\envs\django\lib\site-packages\django\views\generic\base.py", line 62, in view
    self = cls(**initkwargs)
  File "c:\a\envs\django\lib\site-packages\graphene_django\views.py", line 68, in __init__
    schema = graphene_settings.SCHEMA
  File "c:\a\envs\django\lib\site-packages\graphene_django\settings.py", line 110, in __getattr__
    val = perform_import(val, attr)
  File "c:\a\envs\django\lib\site-packages\graphene_django\settings.py", line 54, in perform_import
    return import_from_string(val, setting_name)
  File "c:\a\envs\django\lib\site-packages\graphene_django\settings.py", line 68, in import_from_string
    module = importlib.import_module(module_path)
  File "c:\a\envs\django\lib\importlib\__init__.py", line 109, in import_module
    return _bootstrap._gcd_import(name[level:], package, level)
  File "<frozen importlib._bootstrap>", line 2254, in _gcd_import
  File "<frozen importlib._bootstrap>", line 2237, in _find_and_load
  File "<frozen importlib._bootstrap>", line 2226, in _find_and_load_unlocked
  File "<frozen importlib._bootstrap>", line 1200, in _load_unlocked
  File "<frozen importlib._bootstrap>", line 1129, in _exec
  File "<frozen importlib._bootstrap>", line 1471, in exec_module
  File "<frozen importlib._bootstrap>", line 321, in _call_with_frames_removed
  File "c:\a\programming\django\graphql\src\api\schema.py", line 8, in <module>
    class Query(graphene.ObjectType):
NameError: name 'graphene' is not defined
ERROR "GET /api/graphql/ HTTP/1.1" 500 101985
